Workbook
Name STATION_LIST: #REF!
Name WATERBODY_LIST: #REF!

Sheet tracker
A1: last_updated_date | B1: station | C1: waterbody | D1: county | E1: lease | F1: status | G1: deployment_date | H1: deployment_time_utc | I1: retrieval_date | J1: retrieval_time_utc | K1: deployment_latitude | L1: deployment_longitude | M1: retrieval_latitude | N1: retrieval_longitude | O1: deployment_latitude_n_ddm | P1: deployment_longitude_w_ddm | Q1: retrieval_latitude_n_ddm | R1: retrieval_longitude_w_ddm | S1: sensor_type | T1: sensor_serial_number | U1: sensor_depth_m | V1: string_configuration | W1: sounding_m | X1: acoustic_release | Y1: tide_correction_m | Z1: vr2ar_lug_height_above_seafloor_m | AA1: deployment_tide_direction | AB1: primary_buoy_type | AC1: secondary_buoy_type | AD1: bottom_buoy_type | AE1: whale_safe_link_type | AF1: whale_safe_link_number | AG1: anchor_type | AH1: anchor_weight_kg | AI1: biofouling_prevention | AJ1: datum | AK1: photos_taken | AL1: deployment_attendant | AM1: retrieval_attendant | AN1: notes
A2: 45707 | B2: 1369 | C2: =_xlfn.XLOOKUP(Table3[[#This Row],[station]],station_waterbody_county!A:A, station_waterbody_county!B:B) -> Merigomish Harbour | D2: =_xlfn.XLOOKUP(Table3[[#This Row],[station]],station_waterbody_county!A:A, station_waterbody_county!C:C) -> Pictou | E2: 1369 | F2: retrieved | G2: 45461 | I2: 45547 | K2: 45.654697 | L2: -62.429509 | S2: aquaMeasure SAL | T2: 686013 | U2: 1 | V2: attached to fixed structure | X2: n | AJ2: WGS84 | AK2: n | AL2: Ramon Filgueira (dal) | AM2: Ramon Filgueira (dal) | AN2: Deployed by Ramon Filgueira's lab on Shandaph Oysters lease. Sensors were moved in the fall from 1369 to Robinson Cove at an unknown date. Start/End dates derived from data signal. Use caution.
A3: 45707 | B3: 1369 | C3: =_xlfn.XLOOKUP(Table3[[#This Row],[station]],station_waterbody_county!A:A, station_waterbody_county!B:B) -> Merigomish Harbour | D3: =_xlfn.XLOOKUP(Table3[[#This Row],[station]],station_waterbody_county!A:A, station_waterbody_county!C:C) -> Pictou | E3: 1369 | F3: retrieved | G3: 45461 | I3: 45547 | K3: 45.654697 | L3: -62.429509 | S3: aquaMeasure CHL | T3: 687039 | U3: 1 | V3: attached to fixed structure | X3: n | AJ3: WGS84 | AK3: n | AL3: Ramon Filgueira (dal) | AM3: Ramon Filgueira (dal) | AN3: Deployed by Ramon Filgueira's lab on Shandaph Oysters lease. Sensors were moved in the fall from 1369 to Robinson Cove at an unknown date. Start/End dates derived from data signal. Use caution.
A4: 45707 | B4: 1369 | C4: =_xlfn.XLOOKUP(Table3[[#This Row],[station]],station_waterbody_county!A:A, station_waterbody_county!B:B) -> Merigomish Harbour | D4: =_xlfn.XLOOKUP(Table3[[#This Row],[station]],station_waterbody_county!A:A, station_waterbody_county!C:C) -> Pictou | E4: 1369 | F4: retrieved | G4: 45461 | I4: 45547 | K4: 45.654697 | L4: -62.429509 | S4: aquaMeasure DOT | T4: 671009 | U4: 1 | V4: attached to fixed structure | X4: n | AJ4: WGS84 | AK4: n | AL4: Ramon Filgueira (dal) | AM4: Ramon Filgueira (dal) | AN4: Deployed by Ramon Filgueira's lab on Shandaph Oysters lease. Sensors were moved in the fall from 1369 to Robinson Cove at an unknown date. Start/End dates derived from data signal. Use caution.
A5: 45596 | B5: 1442 | C5: =_xlfn.XLOOKUP(Table3[[#This Row],[station]],station_waterbody_county!A:A, station_waterbody_county!B:B) -> Antigonish Harbour | D5: =_xlfn.XLOOKUP(Table3[[#This Row],[station]],station_waterbody_county!A:A, station_waterbody_county!C:C) -> Antigonish | E5: 1442 | F5: retrieved | G5: 45428 | H5: 0.73263889 | I5: 45583 | J5: 0.69652778 | O5: 45 40.297 | P5: 61 53.557 | Q5: 45 40.295 | R5: 61 53.548 | S5: aquaMeasure DOT | T5: 671304 | U5: 0 | V5: surface buoy | X5: n | AA5: rising | AG5: 2 rotors | AH5: 16 | AI5: none | AJ5: WGS84 | AK5: n | AL5: Anne, TPO | AM5: Anne, Ernie Porter | AN5: cylindrical buoy
A6: 45596 | B6: 1442 | C6: =_xlfn.XLOOKUP(Table3[[#This Row],[station]],station_waterbody_county!A:A, station_waterbody_county!B:B) -> Antigonish Harbour | D6: =_xlfn.XLOOKUP(Table3[[#This Row],[station]],station_waterbody_county!A:A, station_waterbody_county!C:C) -> Antigonish | E6: 1442 | F6: retrieved | G6: 45428 | H6: 0.73263889 | I6: 45583 | J6: 0.69652778 | O6: 45 40.297 | P6: 61 53.557 | Q6: 45 40.295 | R6: 61 53.548 | S6: HOBO Pro V2 | T6: 21981722 | U6: 0.5 | V6: surface buoy | X6: n | AA6: rising | AG6: 2 rotors | AH6: 16 | AI6: none | AJ6: WGS84 | AK6: n | AL6: Anne, TPO | AM6: Anne, Ernie Porter | AN6: cylindrical buoy
A7: 45596 | B7: 1442 | C7: =_xlfn.XLOOKUP(Table3[[#This Row],[station]],station_waterbody_county!A:A, station_waterbody_county!B:B) -> Antigonish Harbour | D7: =_xlfn.XLOOKUP(Table3[[#This Row],[station]],station_waterbody_county!A:A, station_waterbody_county!C:C) -> Antigonish | E7: 1442 | F7: retrieved | G7: 45428 | H7: 0.73263889 | I7: 45583 | J7: 0.69652778 | O7: 45 40.297 | P7: 61 53.557 | Q7: 45 40.295 | R7: 61 53.548 | S7: HOBO Pro V2 | T7: 20820323 | U7: 1 | V7: surface buoy | X7: n | AA7: rising | AG7: 2 rotors | AH7: 16 | AI7: none | AJ7: WGS84 | AK7: n | AL7: Anne, TPO | AM7: Anne, Ernie Porter | AN7: cylindrical buoy
A8: 45596 | B8: 1442 | C8: =_xlfn.XLOOKUP(Table3[[#This Row],[station]],station_waterbody_county!A:A, station_waterbody_county!B:B) -> Antigonish Harbour | D8: =_xlfn.XLOOKUP(Table3[[#This Row],[station]],station_waterbody_county!A:A, station_waterbody_county!C:C) -> Antigonish | E8: 1442 | F8: retrieved | G8: 45428 | H8: 0.73263889 | I8: 45583 | J8: 0.69652778 | O8: 45 40.297 | P8: 61 53.557 | Q8: 45 40.295 | R8: 61 53.548 | S8: HOBO Pro V2 | T8: 21043074 | U8: 2 | V8: surface buoy | X8: n | AA8: rising | AG8: 2 rotors | AH8: 16 | AI8: none | AJ8: WGS84 | AK8: n | AL8: Anne, TPO | AM8: Anne, Ernie Porter | AN8: cylindrical buoy
A9: 45596 | B9: 1443 | C9: =_xlfn.XLOOKUP(Table3[[#This Row],[station]],station_waterbody_county!A:A, station_waterbody_county!B:B) -> Antigonish Harbour | D9: =_xlfn.XLOOKUP(Table3[[#This Row],[station]],station_waterbody_county!A:A, station_waterbody_county!C:C) -> Antigonish | E9: 1443 | F9: retrieved | G9: 45477 | H9: 0.77291667 | I9: 45583 | J9: 0.70486111 | O9: 45 40.741 | P9: 61 53.735 | Q9: 45 40.741 | R9: 61 53.746 | S9: aquaMeasure DOT | T9: 675009 | U9: 0 | V9: surface buoy | W9: 2.3 | X9: n | Y9: 0.3 | AA9: slack low | AG9: 2 rotors | AH9: 18 | AI9: none | AJ9: WGS84 | AK9: n | AL9: Anne, John Porter | AM9: Anne, Ernie Porter
A10: 45596 | B10: 1443 | C10: =_xlfn.XLOOKUP(Table3[[#This Row],[station]],station_waterbody_county!A:A, station_waterbody_county!B:B) -> Antigonish Harbour | D10: =_xlfn.XLOOKUP(Table3[[#This Row],[station]],station_waterbody_county!A:A, station_waterbody_county!C:C) -> Antigonish | E10: 1443 | F10: retrieved | G10: 45477 | H10: 0.77291667 | I10: 45583 | J10: 0.70486111 | O10: 45 40.741 | P10: 61 53.735 | Q10: 45 40.741 | R10: 61 53.746 | S10: aquaMeasure SAL | T10: 680324 | U10: 0 | V10: surface buoy | W10: 2.3 | X10: n | Y10: 0.3 | AA10: slack low | AG10: 2 rotors | AH10: 18 | AI10: none | AJ10: WGS84 | AK10: n | AL10: Anne, John Porter | AM10: Anne, Ernie Porter
A11: 45596 | B11: 1443 | C11: =_xlfn.XLOOKUP(Table3[[#This Row],[station]],station_waterbody_county!A:A, station_waterbody_county!B:B) -> Antigonish Harbour | D11: =_xlfn.XLOOKUP(Table3[[#This Row],[station]],station_waterbody_county!A:A, station_waterbody_county!C:C) -> Antigonish | E11: 1443 | F11: retrieved | G11: 45477 | H11: 0.77291667 | I11: 45583 | J11: 0.70486111 | O11: 45 40.741 | P11: 61 53.735 | Q11: 45 40.741 | R11: 61 53.746 | S11: HOBO Pro V2 | T11: 21465797 | U11: 0.5 | V11: surface buoy | W11: 2.3 | X11: n | Y11: 0.3 | AA11: slack low | AG11: 2 rotors | AH11: 18 | AI11: none | AJ11: WGS84 | AK11: n | AL11: Anne, John Porter | AM11: Anne, Ernie Porter
A12: 45596 | B12: 1443 | C12: =_xlfn.XLOOKUP(Table3[[#This Row],[station]],station_waterbody_county!A:A, station_waterbody_county!B:B) -> Antigonish Harbour | D12: =_xlfn.XLOOKUP(Table3[[#This Row],[station]],station_waterbody_county!A:A, station_waterbody_county!C:C) -> Antigonish | E12: 1443 | F12: retrieved | G12: 45477 | H12: 0.77291667 | I12: 45583 | J12: 0.70486111 | O12: 45 40.741 | P12: 61 53.735 | Q12: 45 40.741 | R12: 61 53.746 | S12: HOBO Pro V2 | T12: 21981721 | U12: 1 | V12: surface buoy | W12: 2.3 | X12: n | Y12: 0.3 | AA12: slack low | AG12: 2 rotors | AH12: 18 | AI12: none | AJ12: WGS84 | AK12: n | AL12: Anne, John Porter | AM12: Anne, Ernie Porter
A13: 45596 | B13: 1443 | C13: =_xlfn.XLOOKUP(Table3[[#This Row],[station]],station_waterbody_county!A:A, station_waterbody_county!B:B) -> Antigonish Harbour | D13: =_xlfn.XLOOKUP(Table3[[#This Row],[station]],station_waterbody_county!A:A, station_waterbody_county!C:C) -> Antigonish | E13: 1443 | F13: retrieved | G13: 45477 | H13: 0.77291667 | I13: 45583 | J13: 0.70486111 | O13: 45 40.741 | P13: 61 53.735 | Q13: 45 40.741 | R13: 61 53.746 | S13: HOBO Pro V2 | T13: 20291437 | U13: 2 | V13: surface buoy | W13: 2.3 | X13: n | Y13: 0.3 | AA13: slack low | AG13: 2 rotors | AH13: 18 | AI13: none | AJ13: WGS84 | AK13: n | AL13: Anne, John Porter | AM13: Anne, Ernie Porter
A14: 45946 | B14: Barachois | C14: =_xlfn.XLOOKUP(Table3[[#This Row],[station]],station_waterbody_county!A:A, station_waterbody_county!B:B) -> Indian Harbour | D14: =_xlfn.XLOOKUP(Table3[[#This Row],[station]],station_waterbody_county!A:A, station_waterbody_county!C:C) -> Guysborough | F14: retrieved | G14: 45623 | H14: 0.59097222 | I14: 45924 | J14: 0.80416667 | K14: 45.084833 | L14: -61.823583 | O14: 45 5.090 | P14: 61 49.415 | Q14: 45 5.085 | R14: 61 49.417 | S14: HOBO Pro V2 | T14: 22048584 | U14: 2 | V14: sub-surface buoy | W14: 12.5 | X14: y | Y14: 0.7 | Z14: 1.6 | AA14: falling | AB14: 14" hard vinyl | AD14: 8" hard vinyl | AG14: 7 rotors | AH14: 60 | AI14: none | AJ14: WGS84 | AK14: y | AL14: Nicole, Paul Keith | AM14: Anne, SOAR | AN14: 2025-10-16: DD changed deployment date to match data and Gantt chart
A15: 45946 | B15: Barachois | C15: =_xlfn.XLOOKUP(Table3[[#This Row],[station]],station_waterbody_county!A:A, station_waterbody_county!B:B) -> Indian Harbour | D15: =_xlfn.XLOOKUP(Table3[[#This Row],[station]],station_waterbody_county!A:A, station_waterbody_county!C:C) -> Guysborough | F15: retrieved | G15: 45623 | H15: 0.59097222 | I15: 45924 | J15: 0.80416667 | K15: 45.084833 | L15: -61.823583 | O15: 45 5.090 | P15: 61 49.415 | Q15: 45 5.085 | R15: 61 49.417 | S15: aquaMeasure DOT | T15: 671428 | U15: 5 | V15: sub-surface buoy | W15: 12.5 | X15: y | Y15: 0.7 | Z15: 1.6 | AA15: falling | AB15: 14" hard vinyl | AD15: 8" hard vinyl | AG15: 7 rotors | AH15: 60 | AI15: none | AJ15: WGS84 | AK15: y | AL15: Nicole, Paul Keith | AM15: Anne, SOAR | AN15: 2025-10-16: DD changed deployment date to match data and Gantt chart
A16: 45946 | B16: Barachois | C16: =_xlfn.XLOOKUP(Table3[[#This Row],[station]],station_waterbody_county!A:A, station_waterbody_county!B:B) -> Indian Harbour | D16: =_xlfn.XLOOKUP(Table3[[#This Row],[station]],station_waterbody_county!A:A, station_waterbody_county!C:C) -> Guysborough | F16: retrieved | G16: 45623 | H16: 0.59097222 | I16: 45924 | J16: 0.80416667 | K16: 45.084833 | L16: -61.823583 | O16: 45 5.090 | P16: 61 49.415 | Q16: 45 5.085 | R16: 61 49.417 | S16: aquaMeasure SAL | T16: 686011 | U16: 5 | V16: sub-surface buoy | W16: 12.5 | X16: y | Y16: 0.7 | Z16: 1.6 | AA16: falling | AB16: 14" hard vinyl | AD16: 8" hard vinyl | AG16: 7 rotors | AH16: 60 | AI16: none | AJ16: WGS84 | AK16: y | AL16: Nicole, Paul Keith | AM16: Anne, SOAR | AN16: 2025-10-16: DD changed deployment date to match data and Gantt chart
A17: 45946 | B17: Barachois | C17: =_xlfn.XLOOKUP(Table3[[#This Row],[station]],station_waterbody_county!A:A, station_waterbody_county!B:B) -> Indian Harbour | D17: =_xlfn.XLOOKUP(Table3[[#This Row],[station]],station_waterbody_county!A:A, station_waterbody_county!C:C) -> Guysborough | F17: retrieved | G17: 45623 | H17: 0.59097222 | I17: 45924 | J17: 0.80416667 | K17: 45.084833 | L17: -61.823583 | O17: 45 5.090 | P17: 61 49.415 | Q17: 45 5.085 | R17: 61 49.417 | S17: HOBO Pro V2 | T17: 22055913 | U17: 10 | V17: sub-surface buoy | W17: 12.5 | X17: y | Y17: 0.7 | Z17: 1.6 | AA17: falling | AB17: 14" hard vinyl | AD17: 8" hard vinyl | AG17: 7 rotors | AH17: 60 | AI17: none | AJ17: WGS84 | AK17: y | AL17: Nicole, Paul Keith | AM17: Anne, SOAR | AN17: 2025-10-16: DD changed deployment date to match data and Gantt chart
A18: 45946 | B18: Barachois | C18: =_xlfn.XLOOKUP(Table3[[#This Row],[station]],station_waterbody_county!A:A, station_waterbody_county!B:B) -> Indian Harbour | D18: =_xlfn.XLOOKUP(Table3[[#This Row],[station]],station_waterbody_county!A:A, station_waterbody_county!C:C) -> Guysborough | F18: retrieved | G18: 45623 | H18: 0.59097222 | I18: 45924 | J18: 0.80416667 | K18: 45.084833 | L18: -61.823583 | O18: 45 5.090 | P18: 61 49.415 | Q18: 45 5.085 | R18: 61 49.417 | S18: VR2AR | T18: 548040 | U18: 10 | V18: sub-surface buoy | W18: 12.5 | X18: y | Y18: 0.7 | Z18: 1.6 | AA18: falling | AB18: 14" hard vinyl | AD18: 8" hard vinyl | AG18: 7 rotors | AH18: 60 | AI18: none | AJ18: WGS84 | AK18: y | AL18: Nicole, Paul Keith | AM18: Anne, SOAR | AN18: 2025-10-16: DD changed deployment date to match data and Gantt chart
A19: 45944 | B19: Barren Island | C19: =_xlfn.XLOOKUP(Table3[[#This Row],[station]],station_waterbody_county!A:A, station_waterbody_county!B:B) -> Marie Joseph Harbour | D19: =_xlfn.XLOOKUP(Table3[[#This Row],[station]],station_waterbody_county!A:A, station_waterbody_county!C:C) -> Guysborough | F19: retrieved | G19: 45547 | H19: 0.69930556 | I19: 45925 | J19: 0.69444444 | O19: 44 57.017 | P19: 62 0.681 | Q19: 44 57.003 | R19: 62 0.679 | S19: HOBO Pro V2 | T19: 21414864 | U19: 2 | V19: sub-surface buoy | W19: 16.5 | X19: y | Y19: 1.6 | Z19: 0.5 | AA19: slack high | AB19: 14" hard vinyl | AD19: 8" hard vinyl | AG19: 7 rotors | AH19: 60 | AI19: none | AJ19: WGS84 | AL19: Anne, SOAR | AM19: Anne, SOAR
A20: 45944 | B20: Barren Island | C20: =_xlfn.XLOOKUP(Table3[[#This Row],[station]],station_waterbody_county!A:A, station_waterbody_county!B:B) -> Marie Joseph Harbour | D20: =_xlfn.XLOOKUP(Table3[[#This Row],[station]],station_waterbody_county!A:A, station_waterbody_county!C:C) -> Guysborough | F20: retrieved | G20: 45547 | H20: 0.69930556 | I20: 45925 | J20: 0.69444444 | O20: 44 57.017 | P20: 62 0.681 | Q20: 44 57.003 | R20: 62 0.679 | S20: aquaMeasure DOT | T20: 675016 | U20: 5 | V20: sub-surface buoy | W20: 16.5 | X20: y | Y20: 1.6 | Z20: 0.5 | AA20: slack high | AB20: 14" hard vinyl | AD20: 8" hard vinyl | AG20: 7 rotors | AH20: 60 | AI20: none | AJ20: WGS84 | AL20: Anne, SOAR | AM20: Anne, SOAR
A21: 45944 | B21: Barren Island | C21: =_xlfn.XLOOKUP(Table3[[#This Row],[station]],station_waterbody_county!A:A, station_waterbody_county!B:B) -> Marie Joseph Harbour | D21: =_xlfn.XLOOKUP(Table3[[#This Row],[station]],station_waterbody_county!A:A, station_waterbody_county!C:C) -> Guysborough | F21: retrieved | G21: 45547 | H21: 0.69930556 | I21: 45925 | J21: 0.69444444 | O21: 44 57.017 | P21: 62 0.681 | Q21: 44 57.003 | R21: 62 0.679 | S21: HOBO Pro V2 | T21: 21650150 | U21: 10 | V21: sub-surface buoy | W21: 16.5 | X21: y | Y21: 1.6 | Z21: 0.5 | AA21: slack high | AB21: 14" hard vinyl | AD21: 8" hard vinyl | AG21: 7 rotors | AH21: 60 | AI21: none | AJ21: WGS84 | AL21: Anne, SOAR | AM21: Anne, SOAR
A22: 45944 | B22: Barren Island | C22: =_xlfn.XLOOKUP(Table3[[#This Row],[station]],station_waterbody_county!A:A, station_waterbody_county!B:B) -> Marie Joseph Harbour | D22: =_xlfn.XLOOKUP(Table3[[#This Row],[station]],station_waterbody_county!A:A, station_waterbody_county!C:C) -> Guysborough | F22: retrieved | G22: 45547 | H22: 0.69930556 | I22: 45925 | J22: 0.69444444 | O22: 44 57.017 | P22: 62 0.681 | Q22: 44 57.003 | R22: 62 0.679 | S22: HOBO Pro V2 | T22: 20330413 | U22: 15 | V22: sub-surface buoy | W22: 16.5 | X22: y | Y22: 1.6 | Z22: 0.5 | AA22: slack high | AB22: 14" hard vinyl | AD22: 8" hard vinyl | AG22: 7 rotors | AH22: 60 | AI22: none | AJ22: WGS84 | AL22: Anne, SOAR | AM22: Anne, SOAR
A23: 45944 | B23: Barren Island | C23: =_xlfn.XLOOKUP(Table3[[#This Row],[station]],station_waterbody_county!A:A, station_waterbody_county!B:B) -> Marie Joseph Harbour | D23: =_xlfn.XLOOKUP(Table3[[#This Row],[station]],station_waterbody_county!A:A, station_waterbody_county!C:C) -> Guysborough | F23: retrieved | G23: 45547 | H23: 0.69930556 | I23: 45925 | J23: 0.69444444 | O23: 44 57.017 | P23: 62 0.681 | Q23: 44 57.003 | R23: 62 0.679 | S23: VR2AR | T23: 547096 | U23: 15 | V23: sub-surface buoy | W23: 16.5 | X23: y | Y23: 1.6 | Z23: 0.5 | AA23: slack high | AB23: 14" hard vinyl | AD23: 8" hard vinyl | AG23: 7 rotors | AH23: 60 | AI23: none | AJ23: WGS84 | AL23: Anne, SOAR | AM23: Anne, SOAR
A24: 45678 | B24: Barren Island | C24: =_xlfn.XLOOKUP(Table3[[#This Row],[station]],station_waterbody_county!A:A, station_waterbody_county!B:B) -> Marie Joseph Harbour | D24: =_xlfn.XLOOKUP(Table3[[#This Row],[station]],station_waterbody_county!A:A, station_waterbody_county!C:C) -> Guysborough | F24: retrieved | G24: 45226 | I24: 45547 | J24: 0.68819444 | K24: 44.950242 | L24: -62.011318 | Q24: 44 57.015 | R24: 62 0.680 | S24: HOBO Pro V2 | T24: 20308044 | U24: 2 | V24: sub-surface buoy | W24: 14.8 | X24: y | Y24: 0.3 | Z24: 1.5 | AB24: 14" hard vinyl | AD24: 8" hard vinyl | AG24: 7 rotors | AI24: none | AJ24: WGS84 | AK24: y | AL24: Michelle Plamondon, Albert Spears | AM24: Anne, SOAR
A25: 45678 | B25: Barren Island | C25: =_xlfn.XLOOKUP(Table3[[#This Row],[station]],station_waterbody_county!A:A, station_waterbody_county!B:B) -> Marie Joseph Harbour | D25: =_xlfn.XLOOKUP(Table3[[#This Row],[station]],station_waterbody_county!A:A, station_waterbody_county!C:C) -> Guysborough | F25: retrieved | G25: 45226 | I25: 45547 | J25: 0.68819444 | K25: 44.950242 | L25: -62.011318 | Q25: 44 57.015 | R25: 62 0.680 | S25: aquaMeasure DOT | T25: 670379 | U25: 5 | V25: sub-surface buoy | W25: 14.8 | X25: y | Y25: 0.3 | Z25: 1.5 | AB25: 14" hard vinyl | AD25: 8" hard vinyl | AG25: 7 rotors | AI25: none | AJ25: WGS84 | AK25: y | AL25: Michelle Plamondon, Albert Spears | AM25: Anne, SOAR
A26: 45678 | B26: Barren Island | C26: =_xlfn.XLOOKUP(Table3[[#This Row],[station]],station_waterbody_county!A:A, station_waterbody_county!B:B) -> Marie Joseph Harbour | D26: =_xlfn.XLOOKUP(Table3[[#This Row],[station]],station_waterbody_county!A:A, station_waterbody_county!C:C) -> Guysborough | F26: retrieved | G26: 45226 | I26: 45547 | J26: 0.68819444 | K26: 44.950242 | L26: -62.011318 | Q26: 44 57.015 | R26: 62 0.680 | S26: HOBO Pro V2 | T26: 21434539 | U26: 10 | V26: sub-surface buoy | W26: 14.8 | X26: y | Y26: 0.3 | Z26: 1.5 | AB26: 14" hard vinyl | AD26: 8" hard vinyl | AG26: 7 rotors | AI26: none | AJ26: WGS84 | AK26: y | AL26: Michelle Plamondon, Albert Spears | AM26: Anne, SOAR
A27: 45678 | B27: Barren Island | C27: =_xlfn.XLOOKUP(Table3[[#This Row],[station]],station_waterbody_county!A:A, station_waterbody_county!B:B) -> Marie Joseph Harbour | D27: =_xlfn.XLOOKUP(Table3[[#This Row],[station]],station_waterbody_county!A:A, station_waterbody_county!C:C) -> Guysborough | F27: retrieved | G27: 45226 | I27: 45547 | J27: 0.68819444 | K27: 44.950242 | L27: -62.011318 | Q27: 44 57.015 | R27: 62 0.680 | S27: VR2AR | T27: 551264 | U27: 15 | V27: sub-surface buoy | W27: 14.8 | X27: y | Y27: 0.3 | Z27: 1.5 | AB27: 14" hard vinyl | AD27: 8" hard vinyl | AG27: 7 rotors | AI27: none | AJ27: WGS84 | AK27: y | AL27: Michelle Plamondon, Albert Spears | AM27: Anne, SOAR
A28: 45519 | B28: Bartletts Beach | C28: =_xlfn.XLOOKUP(Table3[[#This Row],[station]],station_waterbody_county!A:A, station_waterbody_county!B:B) -> Green Cove | D28: =_xlfn.XLOOKUP(Table3[[#This Row],[station]],station_waterbody_county!A:A, station_waterbody_county!C:C) -> Digby | F28: lost | G28: 45141 | K28: 44.010187 | L28: -66.186176 | S28: HOBO Pro V2 | T28: 20291475 | U28: 2 | V28: sub-surface buoy | X28: y | Y28: 3.1 | Z28: 1 | AA28: rising | AB28: 8" hard vinyl | AC28: 8" hard vinyl | AD28: 8" hard vinyl | AG28: 7 rotors | AI28: none | AJ28: WGS84 | AK28: y | AL28: Betty Roethlisberger, Michelle Plamondon | AM28: Anne, SOAR | AN28: (Renamed from SN:Cape St. Mary's/WB: Cape Cove on 2023-08-30 to better reflect location); no contact on attempted retrieval in 2024-08-07
A29: 45519 | B29: Bartletts Beach | C29: =_xlfn.XLOOKUP(Table3[[#This Row],[station]],station_waterbody_county!A:A, station_waterbody_county!B:B) -> Green Cove | D29: =_xlfn.XLOOKUP(Table3[[#This Row],[station]],station_waterbody_county!A:A, station_waterbody_county!C:C) -> Digby | F29: lost | G29: 45141 | K29: 44.010187 | L29: -66.186176 | S29: aquaMeasure DOT | T29: 671330 | U29: 2 | V29: sub-surface buoy | X29: y | Y29: 3.1 | Z29: 1 | AA29: rising | AB29: 8" hard vinyl | AC29: 8" hard vinyl | AD29: 8" hard vinyl | AG29: 7 rotors | AI29: none | AJ29: WGS84 | AK29: y | AL29: Betty Roethlisberger, Michelle Plamondon | AM29: Anne, SOAR | AN29: (Renamed from SN:Cape St. Mary's/WB: Cape Cove on 2023-08-30 to better reflect location); no contact on attempted retrieval in 2024-08-07
A30: 45519 | B30: Bartletts Beach | C30: =_xlfn.XLOOKUP(Table3[[#This Row],[station]],station_waterbody_county!A:A, station_waterbody_county!B:B) -> Green Cove | D30: =_xlfn.XLOOKUP(Table3[[#This Row],[station]],station_waterbody_county!A:A, station_waterbody_county!C:C) -> Digby | F30: lost | G30: 45141 | K30: 44.010187 | L30: -66.186176 | S30: VR2AR | T30: 548578 | U30: 5 | V30: sub-surface buoy | X30: y | Y30: 3.1 | Z30: 1 | AA30: rising | AB30: 8" hard vinyl | AC30: 8" hard vinyl | AD30: 8" hard vinyl | AG30: 7 rotors | AI30: none | AJ30: WGS84 | AK30: y | AL30: Betty Roethlisberger, Michelle Plamondon | AM30: Anne, SOAR | AN30: (Renamed from SN:Cape St. Mary's/WB: Cape Cove on 2023-08-30 to better reflect location); no contact on attempted retrieval in 2024-08-07
A31: 45884 | B31: Bartletts Beach | C31: =_xlfn.XLOOKUP(Table3[[#This Row],[station]],station_waterbody_county!A:A, station_waterbody_county!B:B) -> Green Cove | D31: =_xlfn.XLOOKUP(Table3[[#This Row],[station]],station_waterbody_county!A:A, station_waterbody_county!C:C) -> Digby | F31: deployed | G31: 45869 | H31: 0.55 | O31: 44 0.581 | P31: 66 11.150 | S31: HOBO Pro V2 | T31: 22285926 | U31: 2 | V31: sub-surface buoy | W31: 14.3 | X31: y | Y31: 1.2 | Z31: 1 | AA31: slack low | AB31: 11" hard vinyl | AC31: 11" hard vinyl | AD31: 8" hard vinyl | AE31: none | AG31: 7 rotors | AH31: 60 | AI31: none | AJ31: WGS84 | AL31: Anne, SOAR
A32: 45884 | B32: Bartletts Beach | C32: =_xlfn.XLOOKUP(Table3[[#This Row],[station]],station_waterbody_county!A:A, station_waterbody_county!B:B) -> Green Cove | D32: =_xlfn.XLOOKUP(Table3[[#This Row],[station]],station_waterbody_county!A:A, station_waterbody_county!C:C) -> Digby | F32: deployed | G32: 45869 | H32: 0.55 | O32: 44 0.581 | P32: 66 11.150 | S32: VR2AR | T32: 600013 | U32: 5 | V32: sub-surface buoy | W32: 14.3 | X32: y | Y32: 1.2 | Z32: 1 | AA32: slack low | AB32: 11" hard vinyl | AC32: 11" hard vinyl | AD32: 8" hard vinyl | AE32: none | AG32: 7 rotors | AH32: 60 | AI32: none | AJ32: WGS84 | AL32: Anne, SOAR
A33: 45884 | B33: Bartletts Beach | C33: =_xlfn.XLOOKUP(Table3[[#This Row],[station]],station_waterbody_county!A:A, station_waterbody_county!B:B) -> Green Cove | D33: =_xlfn.XLOOKUP(Table3[[#This Row],[station]],station_waterbody_county!A:A, station_waterbody_county!C:C) -> Digby | F33: deployed | G33: 45869 | H33: 0.55 | O33: 44 0.581 | P33: 66 11.150 | S33: HOBO Pro V2 | T33: 22311509 | U33: 5 | V33: sub-surface buoy | W33: 14.3 | X33: y | Y33: 1.2 | Z33: 1 | AA33: slack low | AB33: 11" hard vinyl | AC33: 11" hard vinyl | AD33: 8" hard vinyl | AE33: none | AG33: 7 rotors | AH33: 60 | AI33: none | AJ33: WGS84 | AL33: Anne, SOAR
A34: 45681 | B34: Bay St. Lawrence | C34: =_xlfn.XLOOKUP(Table3[[#This Row],[station]],station_waterbody_county!A:A, station_waterbody_county!B:B) -> Bay St. Lawrence | D34: =_xlfn.XLOOKUP(Table3[[#This Row],[station]],station_waterbody_county!A:A, station_waterbody_county!C:C) -> Victoria | F34: deployed | G34: 45568 | H34: 0.60555556 | K34: 47.013967 | L34: -60.48855 | O34: 47 0.838 | P34: 60 29.313 | S34: HOBO Pro V2 | T34: 20495248 | U34: 2 | V34: sub-surface buoy | W34: 30 | X34: y | Y34: 1 | Z34: 2 | AA34: falling | AB34: 14" hard vinyl | AD34: 8" hard vinyl | AG34: 7 rotors | AH34: 60 | AI34: none | AJ34: WGS84 | AK34: y | AL34: Kiersten Watson, Nicole Torrie | AN34: Had to lift and drag string ~50m after initial deployment location was too shallow. Check VR2 for damage upon retrieval
A35: 45681 | B35: Bay St. Lawrence | C35: =_xlfn.XLOOKUP(Table3[[#This Row],[station]],station_waterbody_county!A:A, station_waterbody_county!B:B) -> Bay St. Lawrence | D35: =_xlfn.XLOOKUP(Table3[[#This Row],[station]],station_waterbody_county!A:A, station_waterbody_county!C:C) -> Victoria | F35: deployed | G35: 45568 | H35: 0.60555556 | K35: 47.013967 | L35: -60.48855 | O35: 47 0.838 | P35: 60 29.313 | S35: aquaMeasure DOT | T35: 670373 | U35: 5 | V35: sub-surface buoy | W35: 30 | X35: y | Y35: 1 | Z35: 2 | AA35: falling | AB35: 14" hard vinyl | AD35: 8" hard vinyl | AG35: 7 rotors | AH35: 60 | AI35: none | AJ35: WGS84 | AK35: y | AL35: Kiersten Watson, Nicole Torrie | AN35: Had to lift and drag string ~50m after initial deployment location was too shallow. Check VR2 for damage upon retrieval
A36: 45681 | B36: Bay St. Lawrence | C36: =_xlfn.XLOOKUP(Table3[[#This Row],[station]],station_waterbody_county!A:A, station_waterbody_county!B:B) -> Bay St. Lawrence | D36: =_xlfn.XLOOKUP(Table3[[#This Row],[station]],station_waterbody_county!A:A, station_waterbody_county!C:C) -> Victoria | F36: deployed | G36: 45568 | H36: 0.60555556 | K36: 47.013967 | L36: -60.48855 | O36: 47 0.838 | P36: 60 29.313 | S36: HOBO Pro V2 | T36: 20900975 | U36: 10 | V36: sub-surface buoy | W36: 30 | X36: y | Y36: 1 | Z36: 2 | AA36: falling | AB36: 14" hard vinyl | AD36: 8" hard vinyl | AG36: 7 rotors | AH36: 60 | AI36: none | AJ36: WGS84 | AK36: y | AL36: Kiersten Watson, Nicole Torrie | AN36: Had to lift and drag string ~50m after initial deployment location was too shallow. Check VR2 for damage upon retrieval
A37: 45681 | B37: Bay St. Lawrence | C37: =_xlfn.XLOOKUP(Table3[[#This Row],[station]],station_waterbody_county!A:A, station_waterbody_county!B:B) -> Bay St. Lawrence | D37: =_xlfn.XLOOKUP(Table3[[#This Row],[station]],station_waterbody_county!A:A, station_waterbody_county!C:C) -> Victoria | F37: deployed | G37: 45568 | H37: 0.60555556 | K37: 47.013967 | L37: -60.48855 | O37: 47 0.838 | P37: 60 29.313 | S37: HOBO Pro V2 | T37: 20291435 | U37: 15 | V37: sub-surface buoy | W37: 30 | X37: y | Y37: 1 | Z37: 2 | AA37: falling | AB37: 14" hard vinyl | AD37: 8" hard vinyl | AG37: 7 rotors | AH37: 60 | AI37: none | AJ37: WGS84 | AK37: y | AL37: Kiersten Watson, Nicole Torrie | AN37: Had to lift and drag string ~50m after initial deployment location was too shallow. Check VR2 for damage upon retrieval
A38: 45681 | B38: Bay St. Lawrence | C38: =_xlfn.XLOOKUP(Table3[[#This Row],[station]],station_waterbody_county!A:A, station_waterbody_county!B:B) -> Bay St. Lawrence | D38: =_xlfn.XLOOKUP(Table3[[#This Row],[station]],station_waterbody_county!A:A, station_waterbody_county!C:C) -> Victoria | F38: deployed | G38: 45568 | H38: 0.60555556 | K38: 47.013967 | L38: -60.48855 | O38: 47 0.838 | P38: 60 29.313 | S38: HOBO Pro V2 | T38: 20291431 | U38: 20 | V38: sub-surface buoy | W38: 30 | X38: y | Y38: 1 | Z38: 2 | AA38: falling | AB38: 14" hard vinyl | AD38: 8" hard vinyl | AG38: 7 rotors | AH38: 60 | AI38: none | AJ38: WGS84 | AK38: y | AL38: Kiersten Watson, Nicole Torrie | AN38: Had to lift and drag string ~50m after initial deployment location was too shallow. Check VR2 for damage upon retrieval
A39: 45681 | B39: Bay St. Lawrence | C39: =_xlfn.XLOOKUP(Table3[[#This Row],[station]],station_waterbody_county!A:A, station_waterbody_county!B:B) -> Bay St. Lawrence | D39: =_xlfn.XLOOKUP(Table3[[#This Row],[station]],station_waterbody_county!A:A, station_waterbody_county!C:C) -> Victoria | F39: deployed | G39: 45568 | H39: 0.60555556 | K39: 47.013967 | L39: -60.48855 | O39: 47 0.838 | P39: 60 29.313 | S39: VR2AR | T39: 549342 | U39: 25 | V39: sub-surface buoy | W39: 30 | X39: y | Y39: 1 | Z39: 2 | AA39: falling | AB39: 14" hard vinyl | AD39: 8" hard vinyl | AG39: 7 rotors | AH39: 60 | AI39: none | AJ39: WGS84 | AK39: y | AL39: Kiersten Watson, Nicole Torrie | AN39: Had to lift and drag string ~50m after initial deployment location was too shallow. Check VR2 for damage upon retrieval
A40: 45632 | B40: BDLS-1108 | C40: =_xlfn.XLOOKUP(Table3[[#This Row],[station]],station_waterbody_county!A:A, station_waterbody_county!B:B) -> Lochmore Harbour | D40: =_xlfn.XLOOKUP(Table3[[#This Row],[station]],station_waterbody_county!A:A, station_waterbody_county!C:C) -> Cape Breton | F40: retrieved | G40: 45517 | I40: 45594 | K40: 45.894472 | L40: -60.572278 | S40: aquaMeasure SAL | T40: 687479 | U40: 0.9 | V40: attached to fixed structure | W40: 0.9 | X40: n | AG40: cement block | AI40: none | AJ40: WGS84 | AK40: n | AL40: Sindy Dove & Rod Beresford (CBU) | AM40: Sindy Dove & Rod Beresford (CBU) | AN40: Deployed by CBU for MSX monitoring; Limited metadata. Do not include in CMP datasets or reports
...

Sheet station_waterbody_county
A1: station | B1: waterbody | C1: county | D1: latitude | E1: longitude | F1: latitude_ddm | G1: longitude_ddm | H1: status | I1: notes
A2: 1042 | B2: Annapolis Basin | C2: Annapolis | D2: 44.65286 | E2: -65.67453 | F2: 44 39.1716 N | G2: 65 40.4718 W | H2: retired
A3: 5004 | B3: Annapolis Basin | C3: Annapolis | D3: 44.67657 | E3: -65.69118 | F3: 44 40.5942 N | G3: 65 41.4708 W | H3: retired
A4: 5005 | B4: Annapolis Basin | C4: Annapolis | D4: 44.63417 | E4: -65.71193 | F4: 44 38.0502 N | G4: 65 42.7158 W | H4: retired
A5: 5006 | B5: Annapolis Basin | C5: Annapolis | D5: 44.66958 | E5: -65.64773 | F5: 44 40.1748 N | G5: 65 38.8638 W | H5: retired
A6: Cornwallis | B6: Annapolis Basin | C6: Annapolis | D6: 44.6694 | E6: -65.64478 | F6: 44 40.164 N | G6: 65 38.6868 W | H6: retired
A7: Lobster Ledge | B7: Annapolis Basin | C7: Annapolis | D7: 44.67821 | E7: -65.68335 | F7: 44 40.6926 N | G7: 65 41.001 W | H7: retired
A8: 1442 | B8: Antigonish Harbour | C8: Antigonish | D8: 45.671617 | E8: -61.892617 | F8: 45 40.297 N | G8: 61 53.557 W | H8: retired
A9: 1443 | B9: Antigonish Harbour | C9: Antigonish | D9: 45.679017 | E9: -61.895583 | F9: 45 40.741 N | G9: 61 53.735 W | H9: retired
A10: Southside | B10: Antigonish Harbour | C10: Antigonish | D10: 45.65977 | E10: -61.90426 | F10: 45 39.5862 N | G10: 61 54.2556 W | H10: active
A11: 667 | B11: Arichat Harbour | C11: Richmond | D11: 45.49341 | E11: -61.01947 | F11: 45 29.6046 N | G11: 61 1.1682 W | H11: retired
A12: 0716 Center | B12: Arichat Harbour | C12: Richmond | D12: 45.50135 | E12: -61.04197 | F12: 45 30.081 N | G12: 61 2.5182 W | H12: retired
A13: Cape Auguet | B13: Arichat Harbour | C13: Richmond | D13: 45.4982 | E13: -61.01917 | F13: 45 29.892 N | G13: 61 1.1502 W | H13: retired
A14: Cape Auguet Bay | B14: Arichat Harbour | C14: Richmond | D14: 45.50036 | E14: -61.0187 | F14: 45 30.0216 N | G14: 61 1.122 W | H14: retired
A15: Eastern Passage | B15: Arichat Harbour | C15: Richmond | D15: 45.49028 | E15: -61.03831 | F15: 45 29.4168 N | G15: 61 2.2986 W | H15: retired
A16: Jerseyman Island | B16: Arichat Harbour | C16: Richmond | D16: 45.49817 | E16: -61.04465 | F16: 45 29.8902 N | G16: 61 2.679 W | H16: active
A17: Kavanagh Point | B17: Arichat Harbour | C17: Richmond | D17: 45.49824 | E17: -61.01931 | F17: 45 29.8944 N | G17: 61 1.1586 W | H17: active
A18: Saddle Island | B18: Aspotogan Harbour | C18: Lunenburg | D18: 44.50335 | E18: -64.0499 | F18: 44 30.201 N | G18: 64 2.994 W | H18: retired
A19: North Harbour | B19: Aspy Bay | C19: Victoria | D19: 46.91123 | E19: -60.47478 | F19: 46 54.6738 N | G19: 60 28.4868 W | H19: retired
A20: North Harbour Beach | B20: Aspy Bay | C20: Victoria | D20: 46.926289 | E20: -60.448709 | F20: 46 55.57734 N | G20: 60 26.92254 W | H20: wishlist
A21: Les Rochers | B21: Bay of Rocks | C21: Richmond | D21: 45.52904 | E21: -60.92601 | F21: 45 31.7424 N | G21: 60 55.5606 W | H21: retired
A22: Bay St. Lawrence | B22: Bay St. Lawrence | C22: Victoria | D22: 47.013967 | E22: -60.48855 | F22: 47 0.838 N | G22: 60 29.313 W | H22: wishlist
A23: Beaver Point | B23: Beaver Harbour | C23: Halifax | D23: 44.87685 | E23: -62.39985 | F23: 44 52.611 N | G23: 62 23.991 W | H23: retired
A24: BDLS-BP | B24: Benacadie Pond | C24: Cape Breton | D24: 45.903139 | E24: -60.72325 | I24: MSX Surveillance (Bras d'Or Lakes Surveillance)
A25: BDLS-OD | B25: Blues Cove | C25: Inverness | D25: 45.900417 | E25: -61.081139 | I25: MSX Surveillance (Bras d'Or Lakes Surveillance)
A26: Pictou Landing | B26: Boat Harbour | C26: Pictou | D26: 45.673656 | E26: -62.637242 | F26: 45 40.41936 N | G26: 62 38.23452 | H26: retired | I26: Deployed by Ramon Filguiera for Boat Harbour Monitoring
A27: Barra Strait N | B27: Bras d'Or Lakes | C27: Victoria | D27: 45.96545 | E27: -60.79936 | F27: 45 57.927 N | G27: 60 47.9616 W | H27: retired
A28: Barra Strait S | B28: Bras d'Or Lakes | C28: Victoria | D28: 45.94698 | E28: -60.80919 | F28: 45 56.8188 N | G28: 60 48.5514 W | H28: retired
A29: Cameron Island | B29: West Bay | C29: Inverness | F29: 45 48.697 N | G29: 61 1.593 W | H29: active
A30: Denys Basin E | B30: Bras d'Or Lakes | C30: Inverness | D30: 45.90399 | E30: -60.99486 | F30: 45 54.2394 N | G30: 60 59.6916 W | H30: retired
A31: Denys Basin W | B31: Bras d'Or Lakes | C31: Inverness | D31: 45.90103 | E31: -61.02866 | F31: 45 54.0618 N | G31: 61 1.7196 W | H31: retired
A32: Cossitt Point | B32: East Bay | C32: Cape Breton | D32: 45.97342 | E32: -60.4702 | F32: 45 58.4052 N | G32: 60 28.212 W | H32: active
A33: East River Marina | B33: East River Bay | C33: Lunenburg | F33: 44 34.65768 N | G33: 64 10.2672 W | H33: active
A34: Great Bras d'Or Channel NE-E | B34: Bras d'Or Lakes | C34: Victoria | D34: 46.25137 | E34: -60.46452 | F34: 46 15.0822 N | G34: 60 27.8712 W | H34: retired
A35: Great Bras d'Or Channel NE-W | B35: Bras d'Or Lakes | C35: Victoria | D35: 46.25548 | E35: -60.47119 | F35: 46 15.3288 N | G35: 60 28.2714 W | H35: retired
A36: Great Bras d'Or Channel SW-E | B36: Bras d'Or Lakes | C36: Victoria | D36: 46.11841 | E36: -60.62659 | F36: 46 7.1046 N | G36: 60 37.5954 W | H36: retired
A37: Great Bras d'Or Channel SW-W | B37: Bras d'Or Lakes | C37: Victoria | D37: 46.12059 | E37: -60.63396 | F37: 46 7.2354 N | G37: 60 38.0376 W | H37: retired
A38: Little Bras d'Or Channel | B38: Bras d'Or Lakes | C38: Cape Breton | D38: 46.29626 | E38: -60.28769 | F38: 46 17.7756 N | G38: 60 17.2614 W | H38: retired
A39: Little Narrows N | B39: Bras d'Or Lakes | C39: Victoria | D39: 45.99898 | E39: -60.97434 | F39: 45 59.9388 N | G39: 60 58.4604 W | H39: retired
A40: Little Narrows S | B40: Bras d'Or Lakes | C40: Victoria | D40: 45.98641 | E40: -60.99028 | F40: 45 59.1846 N | G40: 60 59.4168 W | H40: retired
...

Sheet column_key
A1: column | B1: description | C1: format | D1: example | E1: dropdown_options
A2: last_updated_date | B2: most recent date any information in this row was updated | C2: yyyy-mm-dd | D2: 45526
A3: station | B3: unique station name | C3: follow spelling format in the Canadian Geographical Names database | D3: Bald Rock | E3: see station_list tab
A4: county | B4: station county
A5: waterbody | B5: station waterbody | C5: follow spelling format in the Canadian Geographical Names database | D5: Antigonish Harbour | E5: see waterbody_list tab
A6: lease | B6: aquaculture lease # station is deployed on (if applicable) | D6: 1443
A7: status | B7: status of sensor | D7: deployed | E7: deployed, retrieved, lost
A8: deployment_date | B8: date of sensor deployment | C8: yyyy-mm-dd | D8: 45404
A9: deployment_time_utc | B9: time of sensor deployment in UTC | C9: hh:mm:ss, 24 hour format, UTC | D9: 0.60625
A10: retrieval_date | B10: date of sensor retrieval | C10: yyyy-mm-dd | D10: 45384
A11: retrieval_time_utc | B11: time of sensor retrieval in UTC | C11: hh:mm:ss, 24 hour format, UTC | D11: 0.60625
A12: deployment_latitude | B12: deployment latitude in decimal degrees | C12: decimal degrees | D12: 43.77043
A13: deployment_longitude | B13: deployment longitude in decimal degrees | C13: decimal degrees | D13: -66.13515
A14: retrieval_latitude | B14: retrieval latitude in decimal degrees | C14: decimal degrees | D14: 44.570148
A15: retrieval_longitude | B15: retrieval longitude in decimal degrees | C15: decimal degrees | D15: -64.034546
A16: deployment_latitude_n_ddm | B16: deployment latitude in degree decimal minutes | C16: degree decimal minutes | D16: 44 34.206
A17: deployment_longitude_w_ddm | B17: deployment longitude in degree decimal minutes | C17: degree decimal minutes | D17: 64 2.063
A18: retrieval_latitude_n_ddm | B18: retrieval latitude in degree decimal minutes | C18: degree decimal minutes | D18: 44 34.208
A19: retrieval_longitude_w_ddm | B19: retrieval longitude in degree decimal minutes | C19: degree decimal minutes | D19: 64 2.07276
A20: sensor_type | B20: sensor type | D20: aquaMeasure DOT | E20: aquaMeasure DOT, aquaMeasure SAL, aquaMeasure CHL, Hobo DO, Hobo Pro V2, Hobo Level Logger, Hobo PH, Tidbit MX2203, miniDOT, VR2AR, VR2ARX
A21: sensor_serial_number | B21: sensor serial number | D21: 680324
A22: sensor_depth_m | B22: sensor depth below surface at low tide in meters, rounded to the nearest 0.5m | D22: 1
A23: string_configuration | B23: configuration of deployed equipment | D23: sub-surface buoy | E23: sub-surface buoy, surface buoy, attached to fixed structure, attached to gear, floating dock, unknown
A24: sounding_m | B24: chart sounding of deployment location in meters | D24: 13.1
A25: acoustic_release | B25: is there an acoustic release sensor on this string? | D25: y | E25: y, n
A26: tide_correction_m | B26: difference between the chart depth and the actual depth (sounding) at time of deployment due to the tide. | C26: tide at deployment time can be viewed on the federal tides website | D26: 0.3
A27: vr2ar_lug_height_above_seafloor_m | B27: deployed height of VR2AR lug above anchor in meters | D27: 1
A28: deployment_tide_direction | B28: direction of tide at time of deployment | D28: rising | E28: rising, falling, slack high, slack low
A29: primary_buoy_type | B29: type of subsurface buoy | D29: 14" hard vinyl | E29: 11" hard vinyl, 14" hard vinyl, 8" hard vinyl, n/a
A30: secondary_buoy_type | B30: type of second subsurface buoy, if applicable (if two buoys are used at the top of the string) | D30: 8" hard vinyl | E30: 11" hard vinyl, 14" hard vinyl, 8" hard vinyl, n/a
A31: bottom_buoy_type | B31: type of buoy above VR2AR | D31: 8" hard vinyl | E31: 11" hard vinyl, 14" hard vinyl, 8" hard vinyl, n/a
A32: whale_safe_link_type | B32: type of whale safe linkage used | D32: SSL link | E32: none, SSL link, Fundy loop
A33: whale_safe_link_number | B33: number of whale safe linkages used | D33: 1
A34: anchor_type | B34: description of anchor | D34: 7 rotors
A35: anchor_weight_kg | B35: weight of anchor in kilograms | D35: 60
A36: biofouling_prevention | B36: type of biofouling prevention applied | D36: none | E36: none, copper tape, copper cage, PME miniWIPER, pvc pipe, uv light, Hobo DO antifouling protective guard
A37: datum | B37: datum of coordinate reference system | D37: WGS84
A38: photos_taken | B38: were photos taken of this string upon deployment or retrieval? | D38: y | E38: y, n
A39: deployment_attendant | B39: names of field staff involved in deployment of equipment | D39: Anne McKee, Greg Trowse
A40: retrieval_attendant | B40: names of field staff involved in retrieval of euquipment | D40: Anne McKee, Greg Trowse
...
